{"name": "test_multiple[2-4-5]", "status": "failed", "statusDetails": {"message": "AssertionError: assert 8 == 5\n  +8\n  -5", "trace": "self = <test_calculator.TestCalculator object at 0x0000017CA0D54E50>, a = 2, b = 4, exc = 5\n\n    @pytest.mark.parametrize('a,b, exc', [\n        (1, 2, 3),\n        (2, 4, 5),\n        (4, 7, 11)\n    ])\n    def test_multiple(self, a, b, exc):\n        result = self.c.multiple(a, b)\n>       assert result == exc\nE       assert 8 == 5\nE         +8\nE         -5\n\ntest_calculator.py:44: AssertionError"}, "parameters": [{"name": "a", "value": "2"}, {"name": "b", "value": "4"}, {"name": "exc", "value": "5"}], "start": 1615726260927, "stop": 1615726260928, "uuid": "825c76e7-eda5-41b7-adf2-ab3c9768ac8e", "historyId": "de1d5b64e85b251b35b64e600108a3f0", "testCaseId": "695a72d0b9108d87efdf02f91f38cbda", "fullName": "test_calculator.TestCalculator#test_multiple", "labels": [{"name": "suite", "value": "test_calculator"}, {"name": "subSuite", "value": "TestCalculator"}, {"name": "host", "value": "FDD-PZSTWIEXCFJ"}, {"name": "thread", "value": "2028-MainThread"}, {"name": "framework", "value": "pytest"}, {"name": "language", "value": "cpython3"}, {"name": "package", "value": "test_calculator"}]}