{"name": "test_multiple[4-7-11]", "status": "failed", "statusDetails": {"message": "AssertionError: assert 28 == 11\n  +28\n  -11", "trace": "self = <test_calculator.TestCalculator object at 0x0000017CA0D78340>, a = 4, b = 7, exc = 11\n\n    @pytest.mark.parametrize('a,b, exc', [\n        (1, 2, 3),\n        (2, 4, 5),\n        (4, 7, 11)\n    ])\n    def test_multiple(self, a, b, exc):\n        result = self.c.multiple(a, b)\n>       assert result == exc\nE       assert 28 == 11\nE         +28\nE         -11\n\ntest_calculator.py:44: AssertionError"}, "parameters": [{"name": "a", "value": "4"}, {"name": "b", "value": "7"}, {"name": "exc", "value": "11"}], "start": 1615726260921, "stop": 1615726260921, "uuid": "f8ccfca4-0e83-4ab9-a2be-a60f02d644e7", "historyId": "5e769c2f4c1e3653bbf5f08ed3b26806", "testCaseId": "695a72d0b9108d87efdf02f91f38cbda", "fullName": "test_calculator.TestCalculator#test_multiple", "labels": [{"name": "suite", "value": "test_calculator"}, {"name": "subSuite", "value": "TestCalculator"}, {"name": "host", "value": "FDD-PZSTWIEXCFJ"}, {"name": "thread", "value": "2028-MainThread"}, {"name": "framework", "value": "pytest"}, {"name": "language", "value": "cpython3"}, {"name": "package", "value": "test_calculator"}]}